Workbook
Name _1NOTES_FIELDS: #REF!
Name _1NOTES_FIELDS: #REF!
Name \0: #REF!
Name \0: #REF!
Name \P: '[1]2010 bud'!#REF!
Name \P: '[1]2010 bud'!#REF!
Name \P: '[1]2010 bud'!#REF!
Name \P: '[2]2011 bud'!#REF!
Name \P: '[3]2011 bud'!#REF!
Name \P: ' bud'!#REF!
Name \P: ' bud'!#REF!
Name a: '[4]Cash Flow-IBS'!#REF!
Name a: '[4]Cash Flow-IBS'!#REF!
Name aa: #REF!
Name aa: #REF!
Name ab: #REF!
Name ac: #REF!
Name ADMIN: #REF!
Name ADMIN: #REF!
Name ADMIN: #REF!
Name ADMIN: #REF!
Name ADMIN: #REF!
Name ADMIN: #REF!
Name ADMIN: #REF!
Name AIRCONDITIONER: '[5]REQUIRED AND BASE INFO'!$C$32
Name AMORT: '[6]2Assumption'!#REF!
Name AmortizationTermYears: #REF!
Name AmortizationTermYears: #REF!
Name AmortizedLoanCosts: #REF!
Name AmortizedLoanCosts: #REF!
Name ANS_INFOPRT: #REF!
Name ANS_INFOPRT: #REF!
Name ANS_KEEPDATA: #REF!
Name ANS_MACROPRT1: #REF!
Name ANS_MACROPRT2: #REF!
Name ANS_MACROPRT3: #REF!
Name ANS_SWAPDATA: #REF!
Name ANS_UPDDATA: #REF!
Name ASSESSMENT: '[5]REQUIRED AND BASE INFO'!$C$33
Name BACKGRND: #REF!
Name BACKGRND: #REF!
Name BalanceOutstanding: #REF!
Name BalanceOutstanding: #REF!
Name BASE: [7]Budget!#REF!
Name BASE: [7]Budget!#REF!
Name BCK_COL: #REF!
Name BCK_COL: #REF!
Name BCK_LOOP: #REF!
Name BCK_LOOP: #REF!
Name Beginning_Balance: -FV(Interest_Rate/12,'Pie Chart for Annual'!Payment_Number-1,-'Pie Chart for Annual'!Monthly_Payment,Loan_Amount)
Name Beginning_Balance: -FV(Interest_Rate/12,Payment_Number-1,-Monthly_Payment,Loan_Amount)
Name BIKE: '[5]REQUIRED AND BASE INFO'!$C$34
Name Body: #REF!
Name Body: #REF!
Name BONUS: '[5]Payroll Data'!$S$34:$S$64
Name Brorrower: #REF!
Name Brorrower: #REF!
Name BUDGET: ' bud'!$A$1:$G$54
Name Ca: #REF!
Name Ca: #REF!

Sheet VLookup Data
A1: 0000-9994 | B1: ASSETS | C1: =SUMIF('yardi_data (2)'!$A:$A,$A1,'yardi_data (2)'!C:C) -> 0 | D1: =SUMIF('yardi_data (2)'!$A:$A,$A1,'yardi_data (2)'!$D:$D) -> 0 | E1: =SUMIF('yardi_data (2)'!$A:$A,$A1,'yardi_data (2)'!$E:$E) -> 0 | F1: =SUMIF('yardi_data (2)'!$A:$A,$A1,'yardi_data (2)'!$F:$F) -> 0 | G1: =SUMIF('yardi_data (2)'!$A:$A,$A1,'yardi_data (2)'!$G:$G) -> 0
A2: 0000-9995 | B2: CASH AND CASH EQUIVALENTS | C2: =SUMIF('yardi_data (2)'!$A:$A,$A2,'yardi_data (2)'!C:C) -> 0 | D2: =SUMIF('yardi_data (2)'!$A:$A,$A2,'yardi_data (2)'!$D:$D) -> 0 | E2: =SUMIF('yardi_data (2)'!$A:$A,$A2,'yardi_data (2)'!$E:$E) -> 0 | F2: =SUMIF('yardi_data (2)'!$A:$A,$A2,'yardi_data (2)'!$F:$F) -> 0 | G2: =SUMIF('yardi_data (2)'!$A:$A,$A2,'yardi_data (2)'!$G:$G) -> 0
A3: 0010-0000 | B3: Operating Account | C3: =SUMIF('yardi_data (2)'!$A:$A,$A3,'yardi_data (2)'!C:C) -> 0 | D3: =SUMIF('yardi_data (2)'!$A:$A,$A3,'yardi_data (2)'!$D:$D) -> 0 | E3: =SUMIF('yardi_data (2)'!$A:$A,$A3,'yardi_data (2)'!$E:$E) -> 0 | F3: =SUMIF('yardi_data (2)'!$A:$A,$A3,'yardi_data (2)'!$F:$F) -> 0 | G3: =SUMIF('yardi_data (2)'!$A:$A,$A3,'yardi_data (2)'!$G:$G) -> 0
A4: 0010-0002 | B4: Operating Account 2 | C4: =SUMIF('yardi_data (2)'!$A:$A,$A4,'yardi_data (2)'!C:C) -> 0 | D4: =SUMIF('yardi_data (2)'!$A:$A,$A4,'yardi_data (2)'!$D:$D) -> 0 | E4: =SUMIF('yardi_data (2)'!$A:$A,$A4,'yardi_data (2)'!$E:$E) -> 0 | F4: =SUMIF('yardi_data (2)'!$A:$A,$A4,'yardi_data (2)'!$F:$F) -> 0 | G4: =SUMIF('yardi_data (2)'!$A:$A,$A4,'yardi_data (2)'!$G:$G) -> 0
A5: 0010-0003 | B5: Payroll Account | C5: =SUMIF('yardi_data (2)'!$A:$A,$A5,'yardi_data (2)'!C:C) -> 0 | D5: =SUMIF('yardi_data (2)'!$A:$A,$A5,'yardi_data (2)'!$D:$D) -> 0 | E5: =SUMIF('yardi_data (2)'!$A:$A,$A5,'yardi_data (2)'!$E:$E) -> 0 | F5: =SUMIF('yardi_data (2)'!$A:$A,$A5,'yardi_data (2)'!$F:$F) -> 0 | G5: =SUMIF('yardi_data (2)'!$A:$A,$A5,'yardi_data (2)'!$G:$G) -> 0
A6: 0010-0004 | B6: Void Exchange | C6: =SUMIF('yardi_data (2)'!$A:$A,$A6,'yardi_data (2)'!C:C) -> 0 | D6: =SUMIF('yardi_data (2)'!$A:$A,$A6,'yardi_data (2)'!$D:$D) -> 0 | E6: =SUMIF('yardi_data (2)'!$A:$A,$A6,'yardi_data (2)'!$E:$E) -> 0 | F6: =SUMIF('yardi_data (2)'!$A:$A,$A6,'yardi_data (2)'!$F:$F) -> 0 | G6: =SUMIF('yardi_data (2)'!$A:$A,$A6,'yardi_data (2)'!$G:$G) -> 0
A7: 0010-0005 | B7: Operating Account 5 | C7: =SUMIF('yardi_data (2)'!$A:$A,$A7,'yardi_data (2)'!C:C) -> 0 | D7: =SUMIF('yardi_data (2)'!$A:$A,$A7,'yardi_data (2)'!$D:$D) -> 0 | E7: =SUMIF('yardi_data (2)'!$A:$A,$A7,'yardi_data (2)'!$E:$E) -> 0 | F7: =SUMIF('yardi_data (2)'!$A:$A,$A7,'yardi_data (2)'!$F:$F) -> 0 | G7: =SUMIF('yardi_data (2)'!$A:$A,$A7,'yardi_data (2)'!$G:$G) -> 0
A8: 0010-0006 | B8: OEF-Checking | C8: =SUMIF('yardi_data (2)'!$A:$A,$A8,'yardi_data (2)'!C:C) -> 0 | D8: =SUMIF('yardi_data (2)'!$A:$A,$A8,'yardi_data (2)'!$D:$D) -> 0 | E8: =SUMIF('yardi_data (2)'!$A:$A,$A8,'yardi_data (2)'!$E:$E) -> 0 | F8: =SUMIF('yardi_data (2)'!$A:$A,$A8,'yardi_data (2)'!$F:$F) -> 0 | G8: =SUMIF('yardi_data (2)'!$A:$A,$A8,'yardi_data (2)'!$G:$G) -> 0
A9: 0010-0099 | B9: Old Operating Accounts | C9: =SUMIF('yardi_data (2)'!$A:$A,$A9,'yardi_data (2)'!C:C) -> 0 | D9: =SUMIF('yardi_data (2)'!$A:$A,$A9,'yardi_data (2)'!$D:$D) -> 0 | E9: =SUMIF('yardi_data (2)'!$A:$A,$A9,'yardi_data (2)'!$E:$E) -> 0 | F9: =SUMIF('yardi_data (2)'!$A:$A,$A9,'yardi_data (2)'!$F:$F) -> 0 | G9: =SUMIF('yardi_data (2)'!$A:$A,$A9,'yardi_data (2)'!$G:$G) -> 0
A10: 0020-0000 | B10: Money Market Account | C10: =SUMIF('yardi_data (2)'!$A:$A,$A10,'yardi_data (2)'!C:C) -> 0 | D10: =SUMIF('yardi_data (2)'!$A:$A,$A10,'yardi_data (2)'!$D:$D) -> 0 | E10: =SUMIF('yardi_data (2)'!$A:$A,$A10,'yardi_data (2)'!$E:$E) -> 0 | F10: =SUMIF('yardi_data (2)'!$A:$A,$A10,'yardi_data (2)'!$F:$F) -> 0 | G10: =SUMIF('yardi_data (2)'!$A:$A,$A10,'yardi_data (2)'!$G:$G) -> 0
A11: 0020-0002 | B11: Money Market Account 2 | C11: =SUMIF('yardi_data (2)'!$A:$A,$A11,'yardi_data (2)'!C:C) -> 0 | D11: =SUMIF('yardi_data (2)'!$A:$A,$A11,'yardi_data (2)'!$D:$D) -> 0 | E11: =SUMIF('yardi_data (2)'!$A:$A,$A11,'yardi_data (2)'!$E:$E) -> 0 | F11: =SUMIF('yardi_data (2)'!$A:$A,$A11,'yardi_data (2)'!$F:$F) -> 0 | G11: =SUMIF('yardi_data (2)'!$A:$A,$A11,'yardi_data (2)'!$G:$G) -> 0
A12: 0020-0003 | B12: Money Market Account 3 | C12: =SUMIF('yardi_data (2)'!$A:$A,$A12,'yardi_data (2)'!C:C) -> 0 | D12: =SUMIF('yardi_data (2)'!$A:$A,$A12,'yardi_data (2)'!$D:$D) -> 0 | E12: =SUMIF('yardi_data (2)'!$A:$A,$A12,'yardi_data (2)'!$E:$E) -> 0 | F12: =SUMIF('yardi_data (2)'!$A:$A,$A12,'yardi_data (2)'!$F:$F) -> 0 | G12: =SUMIF('yardi_data (2)'!$A:$A,$A12,'yardi_data (2)'!$G:$G) -> 0
... A753: 9999-9998 | B753: Total of All | C753: =SUMIF('yardi_data (2)'!$A:$A,$A753,'yardi_data (2)'!C:C) -> 0 | D753: =SUMIF('yardi_data (2)'!$A:$A,$A753,'yardi_data (2)'!$D:$D) -> 0 | E753: =SUMIF('yardi_data (2)'!$A:$A,$A753,'yardi_data (2)'!$E:$E) -> 0 | F753: =SUMIF('yardi_data (2)'!$A:$A,$A753,'yardi_data (2)'!$F:$F) -> 0 | G753: =SUMIF('yardi_data (2)'!$A:$A,$A753,'yardi_data (2)'!$G:$G) -> 0

Sheet yardi_data (2)
C1: 9/1/2015 | D1: 12/1/2015 | F1: tempcen_cf
A2: Cash | B2: Cash
A3: 148 | B3: 148
A4: Oracle
A5: Sql Server | C5: =TEXT(MONTHADD($C$1,-MOD(MONTH($C$1)-1,3)),"mm/dd/yyyy") -> #NAME? | D5: =TEXT(MONTHADD($D$1,-MOD(MONTH($D$1)-1,3)),"mm/dd/yyyy") -> #NAME?
I6: Filter
I7: 1
I8: 1
I9: 1
I10: 1
B11: 444 East 86th Owners Corp | E11: Y-T-D | F11: Y-T-D | G11: 2025 | I11: 1
C12: 2023 | D12: 2024 | E12: 08/2025 | F12: 08/2025 | G12: Budget | I12: 1
A13: GL# | B13: ="Budget "&TEXT($H$12,"0000") -> Budget 0000 | C13: Actual | D13: Actual | E13: Actual | F13: BUDGET | G13: APPROVED | I13: 1
A16: 0000-0000 | B16: CASH FLOW | I16: 1 | J16: 1133606
A18: 0000-0000 | B18: (Header) | I18: 1 | J18: 1133607
A20: 4000-9994 | B20: INCOME | I20: 1 | J20: 1133608
A22: 4000-9995 | B22: RECURRING INCOME | I22: 1 | J22: 1133609
A23: 4010-0000 | B23: Maintenance | C23: 8599731.2 | D23: 8693546.6 | E23: 6012298.2 | F23: 6044653.4 | G23: 9066980 | I23: =C23+D23+E23+F23+G23 -> 38417209 | J23: 1133610
A24: 4011-0000 | B24: Maintenance Sponsors | C24: 0 | D24: 0 | E24: 0 | F24: 0 | G24: 0 | I24: =C24+D24+E24+F24+G24 -> 0 | J24: 1133611
A25: 4020-0000 | B25: Common Charges | C25: 0 | D25: 0 | E25: 0 | F25: 0 | G25: 0 | I25: =C25+D25+E25+F25+G25 -> 0 | J25: 1133612
A26: 4030-0005 | B26: Commercial Common Charges | C26: 0 | D26: 0 | E26: 0 | F26: 0 | G26: 0 | I26: =C26+D26+E26+F26+G26 -> 0 | J26: 1133613
A27: 4021-0000 | B27: Common Charges Sponsors | C27: 0 | D27: 0 | E27: 0 | F27: 0 | G27: 0 | I27: =C27+D27+E27+F27+G27 -> 0 | J27: 1133614
A28: 4025-0000 | B28: Homeowner Association Dues | C28: 0 | D28: 0 | E28: 0 | F28: 0 | G28: 0 | I28: =C28+D28+E28+F28+G28 -> 0 | J28: 1133615
A29: 4030-0000 | B29: Rental Income | C29: 0 | D29: 0 | E29: 0 | F29: 0 | G29: 0 | I29: =C29+D29+E29+F29+G29 -> 0 | J29: 1133616
A30: 4080-0000 | B30: Rents- Residential Below Market | C30: 0 | D30: 0 | E30: 0 | F30: 0 | G30: 0 | I30: =C30+D30+E30+F30+G30 -> 0 | J30: 1133617
A31: 4030-0010 | B31: Vacancy Loss | C31: 0 | D31: 0 | E31: 0 | F31: 0 | G31: 0 | I31: =C31+D31+E31+F31+G31 -> 0 | J31: 1133618
A32: 4040-0000 | B32: Commercial Rent | C32: 52258.06 | D32: 54000 | E32: 36000 | F32: 36000 | G32: 54000 | I32: =C32+D32+E32+F32+G32 -> 232258.06 | J32: 1133619
A33: 4080-0002 | B33: Rents- Commercial Straight Line | C33: 0 | D33: 0 | E33: 0 | F33: 0 | G33: 0 | I33: =C33+D33+E33+F33+G33 -> 0 | J33: 1133620
A34: 4080-0004 | B34: Rents-Commercial Above Market | C34: 0 | D34: 0 | E34: 0 | F34: 0 | G34: 0 | I34: =C34+D34+E34+F34+G34 -> 0 | J34: 1133621
... A91: 4515-0015 | B91: Straight Line Adjustment | C91: 0 | D91: 0 | E91: 0 | F91: 0 | G91: 0 | I91: =C91+D91+E91+F91+G91 -> 0 | J91: 1133678
A92: 4520-0000 | B92: Commercial Real Estate Tax | C92: 0 | D92: 0 | E92: 0 | F92: 0 | G92: 0
A93: 4525-0000 | B93: Porter Wage | C93: 0 | D93: 0 | E93: 0 | F93: 0 | G93: 0 | I93: 1 | J93: 1133679
A94: 4530-0000 | B94: Garage - Operator | C94: 0 | D94: 0 | E94: 0 | F94: 0 | G94: 0 | I94: =C94+D94+E94+F94+G94 -> 0 | J94: 1133680
A95: 4580-0000 | B95: Sales Tax | C95: 0 | D95: 0 | E95: 0 | F95: 0 | G95: 0 | I95: =C95+D95+E95+F95+G95 -> 0 | J95: 1133681
A96: 4600-0000 | B96: Management Fees | C96: 0 | D96: 0 | E96: 0 | F96: 0 | G96: 0 | I96: =C96+D96+E96+F96+G96 -> 0 | J96: 1133682
A97: 4600-0010 | B97: Management Fees-Staff | C97: 0 | D97: 0 | E97: 0 | F97: 0 | G97: 0 | I97: =C97+D97+E97+F97+G97 -> 0 | J97: 1133683
A98: 4605-0000 | B98: Conference Room | C98: 0 | D98: 0 | E98: 0 | F98: 0 | G98: 0 | I98: =C98+D98+E98+F98+G98 -> 0 | J98: 1133684
A99: 4606-0000 | B99: Amenity Rental | C99: 0 | D99: 0 | E99: 0 | F99: 0 | G99: 0 | I99: =C99+D99+E99+F99+G99 -> 0 | J99: 1133685
A100: 4650-0000 | B100: Bad Debt | C100: 0 | D100: 0 | E100: 0 | F100: 0 | G100: 0 | I100: =C100+D100+E100+F100+G100 -> 0 | J100: 1133686
A101: 4655-0000 | B101: N.Y.C. Grant | C101: 0 | D101: 0 | E101: 0 | F101: 0 | G101: 0 | I101: =C101+D101+E101+F101+G101 -> 0 | J101: 1133687
...

Sheet COV
A2: .
C22: For the Board of Directors of
C23: 444 East 86th Street Owners Corp.
C24: =contents!C2 -> Operating Budget
C25: =contents!C3 -> For Year Ending 12/31/2026
E26: Building # | F26: 204
F30: =+' bud'!G5 -> Approved
F31: Prepared By: KP
F32: Reviewd By: MC
F33: =TODAY() -> 46105
C35: 2026 Proposed Increase: | F35: =' bud'!E38 -> -8.7366373e-09

Sheet contents
C1: =+COV!C23 -> 444 East 86th Street Owners Corp.
C2: Operating Budget
C3: =yrlycomp!H3 -> For Year Ending 12/31/2026
B5: TABLE OF CONTENTS
B7: CATEGORY | D7: SCHEDULE | F7: PAGE #
B9: OPERATING BUDGET SUMMARY | D9: - | F9: 1
B11: YEARLY COMPARISON | D11: - | F11: 2
B13: INCOME ANALYSIS | D13: A | F13: 3
B14: COMMERCIAL RENT & ESCALATIONS | D14: A-1 | F14: 4
B16: EXPENSE PIE CHART | D16: - | F16: 5
B18: PAYROLL | D18: B | F18: 6
B20: ELECTRIC | D20: C | F20: 7 & 8
B22: GAS-COOKING | D22: D | F22: 9
B24: GAS -HEATING | D24: E | F24: 10
B26: SUPPLIES, REPAIRS, & MAINTENANCE | D26: F | F26: 11
B28: GENERAL & ADMINISTRATIVE | D28: F-1 | F28: 12
B29: PROFESSIONAL FEES
B30: ADMINISTRATIVE
B31: INSURANCE
B32: CORPORATE TAX
B33: FINANCIAL EXPENSES
B35: WATER & SEWER | D35: G | F35: 13
B37: REAL ESTATE TAXES | D37: H | F37: 14
B39: CAPITAL EXPENSES | D39: I | F39: 15
B41: MANAGEMENT FEE LETTER | D41: - | F41: 16-17
B43: ENERGY SCORE | D43: - | F43: 17-18
F79: =+F77+1 -> 1

Sheet  bud
C1: =+COV!C23 -> 444 East 86th Street Owners Corp.
C2: Operating Budget Summary
C3: =yrlycomp!H3 -> For Year Ending 12/31/2026
G5: Approved
B7: Operating Income
B8: =yrlycomp!B10 -> Maintenance | D8: =yrlycomp!L10 -> 9384324.6
B9: =yrlycomp!B12 -> Commercial | D9: =yrlycomp!L12 -> 54000
B10: Gaarage | D10: =yrlycomp!L13 -> 460000
B11: =yrlycomp!B11 -> Tax Benefit Credits (Abatement, Star,etc) | D11: =yrlycomp!L11 -> -830104.75
B12: =+yrlycomp!B15 -> Storage Income | D12: =+yrlycomp!L15 -> 61380
B13: =yrlycomp!B16 -> Bicycle Charge | D13: =yrlycomp!L16 -> 7380
B14: =yrlycomp!B17 -> Laundry | D14: =yrlycomp!L17 -> 52999.92
B15: =yrlycomp!B18 -> Assessment - Operating | D15: =yrlycomp!L18 -> 200448
B16: =yrlycomp!B14 -> Commercial Real Estate Tax | D16: =yrlycomp!L14 -> 0
B17: =yrlycomp!B19 -> Other Income | D17: =yrlycomp!L19 -> 44000
B18: Total Income | D18: =SUM(D8:D17) -> 9434427.8
B20: Operating Expenses
B21: =+yrlycomp!B23 -> Payroll | D21: =+yrlycomp!L23 -> 1540644.7
B22: =+yrlycomp!B24 -> Electric | D22: =+yrlycomp!L24 -> 251140.76
B23: =+yrlycomp!B25 -> Gas Cooking / Heating | D23: =+yrlycomp!L25 -> 569699.59
B24: =+yrlycomp!B27 -> Water & Sewer | D24: =+yrlycomp!L27 -> 216507.32
B25: =+yrlycomp!B28 -> Supplies | D25: =+yrlycomp!L28 -> 90000
B26: =+yrlycomp!B29 -> Repairs & Maintenance | D26: =+yrlycomp!L29 -> 675000.26
B27: =+yrlycomp!B30 -> Insurance | D27: =+yrlycomp!L30 -> 641578.18
B28: =+yrlycomp!B31 -> Real Estate Taxes | D28: =+yrlycomp!L31 -> 5106995
B29: =+yrlycomp!B32 -> Real Estate Tax Benefit Credits | D29: =+yrlycomp!L32 -> -838405.79
B30: =+yrlycomp!B33 -> Corporate Taxes | D30: =+yrlycomp!L33 -> 24500
B31: =+yrlycomp!B34 -> Professional Fees | D31: =+yrlycomp!L34 -> 178772.6
B32: =+yrlycomp!B35 -> Administrative & Other | D32: =+yrlycomp!L35 -> 87575
B33: =+yrlycomp!B36 -> Financial Expenses | D33: =+yrlycomp!L36 -> 890420.12
B34: Total Expenses | D34: =SUM(D21:D33) -> 9434427.7
B36: Operating Surplus < Deficit> | D36: =D18-D34 -> 0.081987441
B38: Maintenance Increase Needed to Cover <Deficit> | E38: =+D36/D8*-1 -> -8.7366373e-09
B41: Cash & Cash Equivalents
F42: G/L
C43: Webster Bank Operating Account | F43: 0010-0000 | G43: 311669.03
C44: Webster Bank Reserve | F44: 0020-0000 | G44: 1606538.7
C45: NCB | F45: 0035-0002 | G45: 529378.86
C46: Webster Bank Tax Escrow | F46: 0055-0007 | G46: 769146.39
C47: Bank United Escrow Deposit | F47: 0055-0000 | G47: 48295.42
...

Sheet yrlycomp
H1: =+' bud'!C1 -> 444 East 86th Street Owners Corp.
H2: Yearly Comparison | N2: Income - Operating assessment amount is used to help balance the budget and control the amount of the increase.
H3: For Year Ending 12/31/2026 | N3: Leave the same amount used in prevoius years budget until the Board advises to change it
N5: update years column M
D7: 2021 | E7: 2022 | F7: 2023 | G7: 2024 | H7: 2025 | I7: =H7 -> 2025 | J7: =I7 -> 2025 | K7: =J7 -> 2025 | L7: =K7+1 -> 2026 | M7: 2026 Budget
D8: Actual * | E8: Actual * | F8: Actual * | G8: Actual * | H8: 8 Mo. Actual | I8: 4 Mo. Est** | J8: 12 Mo. Forecast | K8: Budget | L8: Budget | M8: V. 2025 Forecast
B9: Income
B10: Maintenance | D10: 7922916 | E10: 8140848 | F10: 8588595 | G10: 8760380 | H10: =SUMIF('VLookup Data'!$A:$A,'VLookup Data'!A235,'VLookup Data'!$E:$E)+SUMIF('VLookup Data'!$A:$A,'VLookup Data'!A247,'VLookup Data'!$E:$E)++SUMIF('VLookup Data'!$A:$A,'VLookup Data'!A245,'VLookup Data'!$E:$E) -> 6032067.9 | I10: =+J10-H10 -> 3034912.4 | J10: =+Income!H16 -> 9066980.3 | K10: 9066980.3 | L10: =+Income!H18 -> 9384324.6 | M10: =+(L10-J10)/J10 -> 0.035
B11: Tax Benefit Credits (Abatement, Star,etc) | D11: -814837 | E11: -772263 | F11: -778849 | G11: -750999 | H11: =SUMIF('VLookup Data'!$A:$A,'VLookup Data'!A248,'VLookup Data'!$E:$E)+SUMIF('VLookup Data'!$A:$A,'VLookup Data'!A249,'VLookup Data'!$E:$E)+SUMIF('VLookup Data'!$A:$A,'VLookup Data'!A250,'VLookup Data'!$E:$E)+SUMIF('VLookup Data'!$A:$A,'VLookup Data'!A251,'VLookup Data'!$E:$E)+SUMIF('VLookup Data'!$A:$A,'VLookup Data'!A252,'VLookup Data'!$E:$E) -> -807394.18 | I11: =J11-H11 -> -650 | J11: =-'RE Taxes'!F29 -> -808044.18 | K11: -825636.71 | L11: =-'RE Taxes'!G29 -> -830104.75 | M11: =+(L11-J11)/J11 -> 0.027301189 | N11: =+H11/9 -> -89710.464 | P11: =4+3+3 -> 10
B12: Commercial | C12: (A) | D12: 24000 | E12: 54000 | F12: 54000 | G12: 54000 | H12: =+'Comm Rent & Escalations'!C38 -> 36000 | I12: 1500 | J12: ='Comm Rent & Escalations'!E38 -> 54000 | K12: 54000 | L12: ='Comm Rent & Escalations'!G38 -> 54000 | M12: =+(L12-J12)/J12 -> 0 | P12: =2.5+2.5+2.5 -> 7.5
B13: Garage | C13: (A) | D13: 62945 | E13: 385818 | F13: 463643 | G13: 450963 | H13: ='Comm Rent & Escalations'!C39 -> 344059.74 | I13: ='Comm Rent & Escalations'!D39 -> 114686.58 | J13: ='Comm Rent & Escalations'!E39 -> 458746.32 | K13: 456000 | L13: ='Comm Rent & Escalations'!G39 -> 460000 | M13: =+(L13-J13)/J13 -> 0.0027328394
B14: Commercial Real Estate Tax | D14: 0 | E14: 0 | F14: 0 | H14: =SUMIF('VLookup Data'!$A:$A,'VLookup Data'!A293,'VLookup Data'!$E:$E) -> 0 | I14: 0 | J14: =+'Comm Rent & Escalations'!E40 -> 0 | K14: 0 | L14: =+'Comm Rent & Escalations'!G40 -> 0 | M14: =+(L14-J14)/J14 -> #DIV/0!
B15: Storage Income | D15: 0 | E15: 26830 | F15: 43216 | G15: 57860 | H15: =+'VLookup Data'!E257 -> 36115.75 | I15: =+J15-H15 -> 25264.25 | J15: =Income!I34 -> 61380 | K15: 52980 | L15: =+Income!I37 -> 61380 | M15: =+(L15-J15)/J15 -> 0
B16: Bicycle Charge | D16: 0 | E16: 0 | F16: 0 | G16: 0 | H16: =SUMIF('VLookup Data'!$A:$A,'VLookup Data'!A258,'VLookup Data'!$E:$E) -> 2959.95 | I16: =+J16-H16 -> 4420.05 | J16: =+Income!H43 -> 7380 | K16: 4680 | L16: =+Income!H45 -> 7380 | M16: =+(L16-J16)/J16 -> 0
B17: Laundry | D17: 60000 | E17: 60000 | F17: 60000 | G17: 58250 | H17: =SUMIF('VLookup Data'!$A:$A,'VLookup Data'!A263,'VLookup Data'!$E:$E) -> 49699.94 | I17: =+J17-H17 -> 3299.98 | J17: =+Income!F51 -> 52999.92 | K17: 52999.92 | L17: =+Income!F53 -> 52999.92 | M17: =+(L17-J17)/J17 -> 0 | S17: =+H18+H43 -> 843076.65
B18: Assessment - Operating | C18: (B) | D18: 145000 | E18: 150000 | F18: 238000 | G18: 230000 | H18: ='VLookup Data'!E274 -> 843076.65 | I18: =+J18-H18 -> -621218.65 | J18: =K18 -> 221858 | K18: 221858 | L18: 200448 | M18: =+(L18-J18)/J18 -> -0.096503169 | N18: =+L18/709000 -> 0.28271932 | S18: =-H53 -> -339591.93
B19: Other Income | D19: =823+22500+24629 -> 47952 | E19: =23500+18492+1254 -> 43246 | F19: =23000+38763+3024 -> 64787 | G19: =81112+12500+12573 -> 106185 | H19: =+Income!D78 -> 77494.5 | I19: =+J19-H19 -> 22228.155 | J19: =+Income!F78 -> 99722.655 | K19: 32500 | L19: =+Income!H78 -> 44000 | M19: =+(L19-J19)/J19 -> -0.55877629 | S19: =-H18 -> -843076.65
B20: Total Income | D20: =SUM(D10:D19) -> 7447976 | E20: =SUM(E10:E19) -> 8088479 | F20: =SUM(F10:F19) -> 8733392 | G20: =SUM(G10:G19) -> 8966639 | H20: =SUM(H10:H19) -> 6614080.2 | I20: =SUM(I10:I19) -> 2584442.8 | J20: =SUM(J10:J19) -> 9215023 | K20: =SUM(K10:K19) -> 9116361.5 | L20: =SUM(L10:L19) -> 9434427.8 | M20: =+(L20-J20)/J20 -> 0.023809465 | S20: =SUM(S17:S19) -> -339591.93
N21: Do Not Print(Use these review Projections)
B22: Expenses | N22: Projected Variance Over 2016 Results
B23: Payroll | D23: =1269052+4529 -> 1273581 | E23: =921032+341913+58722 -> 1321667 | F23: =917786+376231+74535 -> 1368552 | G23: =949984+380390+76798 -> 1407172 | H23: =+Payroll!H77 -> 974031.24 | I23: =+J23-H23 -> 509266.31 | J23: =+Payroll!J77 -> 1483297.5 | K23: 1488209.5 | L23: =+Payroll!L77 -> 1540644.7 | M23: =+(L23-J23)/J23 -> 0.038661935 | N23: =(L23-J23)/J23 -> 0.038661935 | P23: =+J23-E23 -> 161630.55 | Q23: =+E23-D23 -> 48086 | R23: =+J23-E23 -> 161630.55
B24: Electric | D24: 224415 | E24: 303451 | F24: 317329 | G24: 206874 | H24: =SUMIF('VLookup Data'!$A:$A,'VLookup Data'!A432,'VLookup Data'!$E:$E) -> 144894.89 | I24: =+J24-H24 -> 108288.92 | J24: =Electric!F37+'Electric 2'!D37 -> 253183.81 | K24: 321913.7 | L24: =Electric!F53+'Electric 2'!D53 -> 251140.76 | M24: =+(L24-J24)/J24 -> -0.0080694374 | N24: =(L24-J24)/J24 -> -0.0080694374 | P24: =+P23/E23 -> 0.12229294 | Q24: =+Q23/D23 -> 0.037756531 | R24: =+R23/E23 -> 0.12229294
B25: Gas Cooking / Heating | D25: 395473 | E25: 466316 | F25: 524865 | G25: 468018 | H25: =SUMIF('VLookup Data'!$A:$A,'VLookup Data'!A429,'VLookup Data'!$E:$E)+SUMIF('VLookup Data'!$A:$A,'VLookup Data'!A431,'VLookup Data'!$E:$E) -> 376764.45 | I25: =+J25-H25 -> 194777.08 | J25: =+'Gas Cooking'!F37+'Gas-Heat'!F37 -> 571541.53 | K25: 535361.39 | L25: =+'Gas Cooking'!F53+'Gas-Heat'!F53 -> 569699.59 | M25: =+(L25-J25)/J25 -> -0.0032227603 | N25: =(L25-J25)/J25 -> -0.0032227603
B26: Fuel | D26: 0 | E26: 0 | F26: 0 | G26: 0 | H26: =SUMIF('VLookup Data'!$A:$A,'VLookup Data'!A433,'VLookup Data'!$E:$E) -> 0 | I26: 0 | J26: 0 | K26: 0 | L26: 0
B27: Water & Sewer | D27: 209320 | E27: 214222 | F27: 211315 | G27: 265390 | H27: =+Water!D39 -> 136280.9 | I27: =+J27-H27 -> 72501.47 | J27: =+Water!G39 -> 208782.37 | K27: 217796.61 | L27: =+Water!I39 -> 216507.32 | M27: =+(L27-J27)/J27 -> 0.037 | N27: =(L27-J27)/J27 -> 0.037
B28: Supplies | D28: =18540+69215 -> 87755 | E28: =17603+61201 -> 78804 | F28: =25923+75818 -> 101741 | G28: =30860+77598 -> 108458 | H28: =+'Repairs & Supplies'!D9 -> 45896.47 | I28: =+J28-H28 -> 20504.12 | J28: =+'Repairs & Supplies'!H9 -> 66400.59 | K28: 90000 | L28: =+'Repairs & Supplies'!J9 -> 90000 | M28: =+(L28-J28)/J28 -> 0.35540964 | N28: =(L28-J28)/J28 -> 0.35540964
B29: Repairs & Maintenance | D29: =596659-69215 -> 527444 | E29: =555982-61201 -> 494781 | F29: =748274-75818 -> 672456 | G29: =768962-77598 -> 691364 | H29: =+'Repairs & Supplies'!D57 -> 519828.15 | I29: =+J29-H29 -> 123363.53 | J29: =+'Repairs & Supplies'!H57 -> 643191.68 | K29: 550000.09 | L29: =+'Repairs & Supplies'!J57 -> 675000.26 | M29: =+(L29-J29)/J29 -> 0.049454274 | N29: =(L29-J29)/J29 -> 0.049454274 | O29: =154580+90267 -> 244847
B30: Insurance | D30: 249055 | E30: 277481 | F30: 336029 | G30: 393544 | H30: =+'Gen & Admin'!D57 -> 557894.07 | I30: =+J30-H30 -> 0 | J30: =+'Gen & Admin'!H57 -> 557894.07 | K30: 501226.29 | L30: =+'Gen & Admin'!J57 -> 641578.18 | M30: =+(L30-J30)/J30 -> 0.15 | N30: =(L30-J30)/J30 -> 0.15 | Q30: 2014 | R30: 2013
B31: Real Estate Taxes | D31: =3777699+814837 -> 4592536 | E31: =3929982+772263+3 -> 4702248 | F31: =3985240+778849 -> 4764089 | G31: =4167342+750999 -> 4918341 | H31: =+'RE Taxes'!D41 -> 3724147.8 | I31: =+J31-H31 -> 1249363.4 | J31: =+'RE Taxes'!F41 -> 4973511.1 | K31: 5087406.1 | L31: =+'RE Taxes'!H41 -> 5106995 | M31: =+(L31-J31)/J31 -> 0.026838956 | N31: =(L31-J31)/J31 -> 0.026838956 | P31: E | Q31: 294056.38 | R31: 277601
B32: Real Estate Tax Benefit Credits | D32: =D11 -> -814837 | E32: =E11 -> -772263 | F32: -778849 | G32: -750999 | H32: =+'RE Taxes'!D46-'RE Taxes'!D41 -> -608282.85 | I32: =+J32-H32 -> -204260.75 | J32: =+'RE Taxes'!F46-'RE Taxes'!F41 -> -812543.6 | K32: -845992.58 | L32: =+'RE Taxes'!H46-'RE Taxes'!H41 -> -838405.79 | M32: =+(L32-J32)/J32 -> 0.031828686 | N32: =(L32-J32)/J32 -> 0.031828686 | P32: G | Q32: 351520 | R32: 121107
B33: Corporate Taxes | D33: =25778+34483 -> 60261 | E33: 49803 | F33: 17268 | G33: 32746 | H33: =+'Gen & Admin'!D60 -> 19550 | I33: =+J33-H33 -> 5664 | J33: =+'Gen & Admin'!H60 -> 25214 | K33: 27300 | L33: ='Gen & Admin'!J61 -> 24500 | M33: =+(L33-J33)/J33 -> -0.028317601 | N33: =(L33-J33)/J33 -> -0.028317601 | Q33: =SUM(Q31:Q32) -> 645576.38 | R33: =SUM(R31:R32) -> 398708 | T33: =+E31-D31 -> 109712 | U33: =+J31+J32 -> 4160967.5
B34: Professional Fees | D34: =55899+672+15750+125667+10267 -> 208255 | E34: =27995+63009+129122 -> 220126 | F34: =20722+33460+132673 -> 186855 | G34: =22715+13186+136322 -> 172223 | H34: =+'Gen & Admin'!D18 -> 116223.15 | I34: =+J34-H34 -> 48844.075 | J34: =+'Gen & Admin'!H18 -> 165067.22 | K34: 175820.63 | L34: =+'Gen & Admin'!J18 -> 178772.6 | M34: =+(L34-J34)/J34 -> 0.083029051 | N34: =(L34-J34)/J34 -> 0.083029051 | P34: =+L34-139000 -> 39772.6 | T34: =+T33/D31 -> 0.023889198 | U34: =+U33-E31 -> -541280.47
B35: Administrative & Other | D35: =15328+31775+26561 -> 73664 | E35: =63175+600+8751 -> 72526 | F35: =61569+350+6724 -> 68643 | G35: =85714+600+7208 -> 93522 | H35: =+'Gen & Admin'!D47 -> 61257.55 | I35: =+J35-H35 -> 13804.55 | J35: =+'Gen & Admin'!H47 -> 75062.1 | K35: 76900 | L35: =+'Gen & Admin'!J47 -> 87575 | M35: =+(L35-J35)/J35 -> 0.16670064 | N35: =(L35-J35)/J35 -> 0.16670064 | U35: =+U34/E31 -> -0.115111
B36: Financial Expenses | D36: =581421+174131 -> 755552 | E36: =618553+181161 -> 799714 | F36: =611214+188474 -> 799688 | G36: =605232+194437 -> 799669 | H36: =+'Gen & Admin'!D68 -> 594030.08 | I36: =+J36-H36 -> 297015.04 | J36: =+'Gen & Admin'!H68 -> 891045.12 | K36: 890420.12 | L36: =+'Gen & Admin'!J68 -> 890420.12 | M36: =+(L36-J36)/J36 -> -0.00070142351 | N36: =(L36-J36)/J36 -> -0.00070142351
B37: Total Expenses | D37: =SUM(D23:D36) -> 7842474 | E37: =SUM(E23:E36) -> 8228876 | F37: =SUM(F23:F36) -> 8589981 | G37: =SUM(G23:G36) -> 8806322 | H37: =SUM(H23:H36) -> 6662515.9 | I37: =SUM(I23:I36) -> 2439131.7 | J37: =SUM(J23:J36) -> 9101647.6 | K37: =SUM(K23:K36) -> 9116361.8 | L37: =SUM(L23:L36) -> 9434427.7 | M37: =+(L37-J37)/J37 -> 0.036562626
B39: Net Operating Surplus <Deficit> | D39: =D20-D37 -> -394498 | E39: =E20-E37 -> -140397 | F39: =F20-F37 -> 143411 | G39: =G20-G37 -> 160317 | H39: =H20-H37 -> -48435.63 | I39: =I20-I37 -> 145311.08 | J39: =J20-J37 -> 113375.45 | K39: -0.33465522 | L39: =L20-L37 -> 0.081987441 | M39: =+(L39-J39)/J39 -> -0.99999928 | N39: =+L39/L10 -> 8.7366373e-09
B41: Non-Operating Income
B42: Capital Assessment | D42: 0 | E42: 0 | H42: 0 | I42: 0 | J42: 0 | K42: 0 | L42: 0 | M42: 0
B43: Special Assessment | C43: (B) | D43: 658816 | E43: 583354 | F43: 843349 | G43: 836993 | H43: 0 | I43: =+J43-H43 -> 644430.14 | J43: =+Income!G24-K18 -> 644430.14 | K43: 644432.69 | L43: =Income!G26-L18 -> 665570.54 | M43: =+(L43-J43)/J43 -> 0.032804788 | N43: Make sure the assessment 12 mo Forecast is equal to the budgeted amount for the current year
B44: Interest Income | D44: 1995 | E44: 58368 | F44: 85128 | G44: 84807 | H44: =SUMIF('VLookup Data'!$A:$A,'VLookup Data'!A334,'VLookup Data'!$E:$E) -> 35230.42 | I44: =+H44/8*4 -> 17615.21 | J44: =SUM(H44:I44) -> 52845.63 | K44: 0 | L44: 0 | M44: =+(L44-J44)/J44 -> -1 | O44: change the interest income formula
...

Sheet Income
E1: =yrlycomp!H1 -> 444 East 86th Street Owners Corp.
E2: Income
B3: Schedule A | E3: =yrlycomp!H3 -> For Year Ending 12/31/2026
A5: G/L
E6: Shares | F6: Mthly $/per sh | G6: Monthly | H6: Annual | I6: Increase | K6: 315 Units
A7: 4010-0000 | B7: Maintenance
D8: 2017 | E8: 398682 | F8: 1.4650472 | G8: =E8*F8 -> 584087.95 | H8: =G8*12 -> 7009055.4 | I8: 0.025
D9: 2018 | E9: 398682 | F9: =+F8*I9+F8 -> 1.5177889 | G9: =E9*F9 -> 605115.11 | H9: =G9*12 -> 7261381.4 | I9: 0.036
D10: 2019 | E10: 398682 | F10: =+F9*I10+F9 -> 1.5709115 | G10: =+E10*F10 -> 626294.14 | H10: =+G10*12 -> 7515529.7 | I10: 0.035
D11: 2020 | E11: 398682 | F11: =+F10*I11+F10 -> 1.614897 | G11: =+E11*F11 -> 643830.38 | H11: =+G11*12 -> 7725964.5 | I11: 0.028
D12: 2021 | E12: 398682 | F12: =+F11*I12+F11 -> 1.6552695 | G12: =+E12*F12 -> 659926.14 | H12: =+G12*12 -> 7919113.7 | I12: 0.025
D13: 2022 | E13: 398682 | F13: =F12*I13+F12 -> 1.701617 | G13: =+E13*F13 -> 678404.07 | H13: =+G13*12 -> 8140848.8 | I13: 0.028
D14: 2023 | E14: 398682 | F14: =F13*I14+F13 -> 1.7952059 | G14: =+E14*F14 -> 715716.29 | H14: =+G14*12 -> 8588595.5 | I14: 0.055
D15: 2024 | E15: 398682 | F15: 1.8311101 | G15: 730030.62 | H15: 8760367.4 | I15: 0.02
D16: 2025 | E16: 398682 | F16: 1.8951989 | G16: 755581.69 | H16: 9066980.3 | I16: 0.035
D18: 2026 Budget | E18: =E16 -> 398682 | F18: =F16*I18+F16 -> 1.9615309 | G18: =+E18*F18 -> 782027.05 | H18: =+G18*12 -> 9384324.6 | I18: 0.035 | K18: =E18*2.52 -> 1004678.6
A20: 4200-0000 | B20: Special Assessment | E20: Shares | F20: $/per Share | G20: Total | H20: Month Billed
D21: 2022 | E21: 398682 | F21: 2.06142 | G21: =+F21*E21 -> 821851.05 | H21: June
D22: 2023 | E22: 398682 | F22: 2.11403 | G22: =+E22*F22 -> 842825.71 | H22: June
B23: (Assessment/Abatement) | D23: 2024 | E23: 398682 | F23: 2.0993937 | G23: =E23*F23 -> 836990.46 | H23: May | J23: Operating Assessment is based on 17.5% of Gross Real Estate Taxes for 2015/2016
D24: 2025 | E24: 398682 | F24: 2.17288 | G24: =E24*F24 -> 866288.14 | H24: May
D26: =D18 -> 2026 Budget | E26: =E24 -> 398682 | F26: =+(('RE Taxes'!I11*2)*17.5%)/Income!E26 -> 2.1722038 | G26: =+E26*F26 -> 866018.54 | H26: May | J26: DO NOT REMOVE FORMULA IN F26
A28: 4130-0010 | B28: Storage Room | C28: (A) | E28: Total Units | F28: Units Occupied | G28: Monthly $/Per Unit | H28: Monthly Fee | I28: Annual Fee
D29: 2025 | N29: 2023 | O29: Storage Fees were reduced after budget approved for 2023
D30: Size A | E30: 18 | F30: 17 | G30: 75 | H30: =F30*G30 -> 1275 | I30: =H30*12 -> 15300 | K30: =E30*G30 -> 1350 | L30: 28-32 cubic feet | N30: 7 vacant
D31: Size B | E31: 14 | F31: 13 | G31: 100 | H31: =G31*F31 -> 1300 | I31: =H31*12 -> 15600 | K31: =E31*G31 -> 1400 | L31: 36 cubic feet | O31: Size A - $75.00
D32: Size C | E32: 16 | F32: 16 | G32: 125 | H32: =G32*F32 -> 2000 | I32: =H32*12 -> 24000 | K32: =E32*G32 -> 2000 | L32: 48 cubic Feet | O32: Size B - $100.00
D33: Size D | E33: 3 | F33: 3 | G33: 180 | H33: =G33*F33 -> 540 | I33: =H33*12 -> 6480 | K33: =E33*G33 -> 540 | O33: Size C - $125.00
D34: Total | E34: =SUM(E30:E33) -> 51 | F34: =SUM(F30:F33) -> 49 | G34: =SUM(G30:G33) -> 480 | H34: =SUM(H30:H33) -> 5115 | I34: =SUM(I30:I33) -> 61380 | K34: =SUM(K30:K33) -> 5290 | L34: monthly at full capacity | O34: Size D - $180.00
D37: =D26 -> 2026 Budget | E37: 51 | F37: =F34 -> 49 | G37: 0 | H37: =H34 -> 5115 | I37: =H37*12 -> 61380
A39: 4130-0015 | B39: Bicycle Storage | C39: (B) | E39: Total Units | F39: Units Occupied | G39: Annual fee | H39: Total | L39: 42 Bike Racks Total
D40: 2022 | F40: 28 | G40: 180 | H40: =F40*G40 -> 5040 | L40: per Jacob - increase for 2022 # of spots
D41: 2023 | F41: 28 | G41: 180 | H41: =F41*G41 -> 5040
D42: 2024 | E42: 43 | F42: 26 | G42: 180 | H42: =F42*G42 -> 4680 | L42: Bicycle Billed monthly $15.00/mo.
D43: 2025 | E43: 43 | F43: 41 | G43: 180 | H43: =F43*G43 -> 7380 | M43: Jan 30 spots
M44: Feb-March-April-Aug-Sept 27 spots
D45: =D37 -> 2026 Budget | E45: 43 | F45: =F43 -> 41 | G45: =G43 -> 180 | H45: =F45*G45 -> 7380
M46: May-June-July-Oct 28 spots
A47: 4130-0030 | B47: Laundry | C47: (C) | E47: Monthly | F47: Annual
C48: (C) | D48: 2022 | E48: 5000 | F48: =+E48*12 -> 60000
...

Sheet Comm Rent & Escalations
D1: =yrlycomp!H1 -> 444 East 86th Street Owners Corp.
D2: Commercial Rent & Escalations
B3: Schedule A-1 | D3: =yrlycomp!H3 -> For Year Ending 12/31/2026
H5: 1/23 new lease Horshinski
C6: COMMERCIAL RENT | H6: 1/13/23-1/12/24 $54,000
B7: Tenant | C7: Period | D7: Rent | E7: Annualized | H7: 1/13/24-1/12/25 $54,000
C9: 2023
C10: Jan - Dec | D10: 4500 | E10: =+D10*12 -> 54000
C11: 2024
C12: Jan - Dec | D12: 4500 | E12: 54000
B13: Corrie Horshinski, D.C. | C13: 2025
C14: Jan - Dec | D14: 4500 | E14: 54000
C15: 2026 | H15: 1/13/25-1/12/26 $54,000
C16: Jan - Dec | D16: 4500 | E16: =+D16*12 -> 54000 | H16: 1/13/26-1/12/27 $54,000
C18: 2025 Payments | D18: Receipt Month | E18: Payments Received
B19: East 86th Street Garage | C19: Nov 2024 | D19: 45664 | E19: 36961.02
C20: Dec 2024 | D20: 45686 | E20: 39945.44
C21: Jan 2025 | D21: 45719 | E21: 44777.36
C22: Feb 2025 | D22: 45743 | E22: 28651.89
C23: March 2025 | D23: 45769 | E23: 34168
C24: April 2025 | D24: 45817 | E24: 46381.33
C25: May 2025 | D25: 45831 | E25: 38783.93
C26: June 2025 | D26: 45862 | E26: 33696.36
C27: July 2025 | D27: 45888 | E27: 40694.41
C28: Aug 2024 | D28: 45561 | E28: 0
C29: Jan-August Totals | E29: =SUM(E19:E28) -> 344059.74
C30: Sept-Dec Estimated | E30: =E29/9*3 -> 114686.58
C32: 2025 Estimated Total | E32: =SUM(E29:E30) -> 458746.32 | H32: =E32/12 -> 38228.86
C34: =+yrlycomp!H7 -> 2025 | D34: =C34 -> 2025 | E34: =D34 -> 2025 | F34: =E34 -> 2025 | G34: =+F34+1 -> 2026
C35: Jan - Aug | D35: Sep - Dec | E35: 12 Month | F35: Budget | G35: Budget
B36: Category | C36: Actual | D36: Est | E36: Forecast
A38: 4040-0000 | B38: Commercial Rent | C38: ='VLookup Data'!E242 -> 36000 | D38: =E38-C38 -> 18000 | E38: =E14 -> 54000 | F38: 54000 | G38: =E16 -> 54000 | I38: fix formula cells in all columns next year
A39: 4135-0010 | B39: Garage | C39: ='VLookup Data'!E268 -> 344059.74 | D39: =E39-C39 -> 114686.58 | E39: =E32 -> 458746.32 | F39: 456000 | G39: 460000
A40: 4520-0000 | B40: Commercial R/E Tax Escalation | C40: =SUMIF('VLookup Data'!$A:$A,A40,'VLookup Data'!$E:$E) -> 0 | D40: =C40*8/4 -> 0 | E40: 0 | F40: 0 | G40: 0
C41: =SUM(C38:C40) -> 380059.74 | D41: =SUM(D38:D40) -> 132686.58 | E41: =SUM(E38:E40) -> 512746.32 | F41: =SUM(F38:F40) -> 510000 | G41: =SUM(G38:G40) -> 514000
A43: *Commercial Lease with Corrie Horshinski, D.C. 01/13/2023-1/12/2027.
A44: *Garage - 444 East 86th Street owns the Garage. Contract with 1623 York Avenue Parking Corp. They pay a management fee of monthly proceeds
A45: based on revenue collected less expenses. 2025 Budget assumes monthly collections of $38,000.00
I46: For 2022 Commercial Rent and Garage Income totals are combined. 2023 Budget will separate and code to separate line items
D62: Page 4

Sheet pyrl
D1: =COV!C23 -> 444 East 86th Street Owners Corp.
D2: Labor & Related
A3: Schedule B | D3: =yrlycomp!H3 -> For Year Ending 12/31/2026
H4: Resident | J4: Ptr/Drmn | K4: Porter
A5: Union: 32 BJ | H5: Manager | I5: Handyman | J5: Concierge | K5: Man (80%) | L5: Total
H6: 1 | I6: 2 | J6: 10 | K6: 3 | L6: =SUM(H6:K6) -> 16
A7: Wages:
A8: Resident Manager | B8: =41.7865*40 -> 1671.46 | C8: /wk | D8: * | E8: 0 | F8: Wks | H8: =B8*E8*H$6 -> 0 | L8: =SUM(H8:K8) -> 0
A9: =+A8 -> Resident Manager | B9: =+B8+25 -> 1696.46 | C9: =+C8 -> /wk | D9: =+D8 -> * | E9: =52-E8 -> 52 | F9: =+F8 -> Wks | H9: =B9*E9*H$6 -> 88215.92 | L9: =SUM(H9:K9) -> 88215.92
A10: =+A8 -> Resident Manager | B10: 0 | C10: /Qtr | D10: =+D9 -> * | E10: 4 | F10: Qtrs | H10: =B10*E10*H$6 -> 0 | L10: =SUM(H10:K10) -> 0
A11: Handyman | B11: =22.3408*40 -> 893.632 | C11: /wk | D11: * | E11: 16 | F11: Wks | I11: =+B11*E11*I6 -> 28596.224 | L11: =SUM(H11:K11) -> 28596.224
A12: =+A11 -> Handyman | B12: =+B11+24 -> 917.632 | C12: =+C11 -> /wk | D12: =+D11 -> * | E12: =52-E11 -> 36 | F12: =+F11 -> Wks | I12: =+B12*E12*I6 -> 66069.504 | L12: =SUM(H12:K12) -> 66069.504
A13: Ptr/Drmn/Concierge | B13: =20.2128*40 -> 808.512 | C13: /wk | D13: * | E13: 16 | F13: Wks | J13: =+B13*E13*J6 -> 129361.92 | L13: =SUM(H13:K13) -> 129361.92
A14: =+A13 -> Ptr/Drmn/Concierge | B14: =+B13+22 -> 830.512 | C14: =+C13 -> /wk | D14: =+D13 -> * | E14: =52-E13 -> 36 | F14: =+F13 -> Wks | J14: =+B14*E14*J6 -> 298984.32 | L14: =SUM(H14:K14) -> 298984.32
A15: Porter | B15: =+B13*80% -> 646.8096 | C15: /wk | D15: * | E15: 16 | F15: Wks | K15: =+B15*E15*K6 -> 31046.861 | L15: =SUM(H15:K15) -> 31046.861
A16: =+A15 -> Porter | B16: =+B14*80% -> 664.4096 | C16: =+C15 -> /wk | D16: =+D15 -> * | E16: =52-E15 -> 36 | F16: =+F15 -> Wks | K16: =+B16*E16*K6 -> 71756.237 | L16: =SUM(H16:K16) -> 71756.237
C17: Total: | H17: =SUM(H8:H16) -> 88215.92 | I17: =SUM(I8:I16) -> 94665.728 | J17: =SUM(J8:J16) -> 428346.24 | K17: =SUM(K8:K16) -> 102803.1 | L17: =SUM(L8:L16) -> 714030.99
B19: Overtime: % of wages @ | E19: 0.002 | H19: =+H17*$E$19 -> 176.43184 | I19: =+I17*$E$19 -> 189.33146 | J19: =+J17*$E$19 -> 856.69248 | K19: =+K17*$E$19 -> 205.6062 | L19: =SUM(H19:K19) -> 1428.062
L20: =SUM(H20:K20) -> 0
A21: Vacation, Sick ,Personal | D21: Union | F21: Coverage | L21: =SUM(H21:K21) -> 0
A22: =+A10 -> Resident Manager | B22: =+B9 -> 1696.46 | C22: * | D22: 4 | E22: WKS.* | F22: 0 | H22: =+B22*F22 -> 0 | L22: =SUM(H22:K22) -> 0
A23: =+A11 -> Handyman | B23: =+B12 -> 917.632 | C23: * | D23: 7 | E23: WKS.* | F23: 4 | I23: =+B23*F23 -> 3670.528 | L23: =SUM(H23:K23) -> 3670.528
A24: =+A13 -> Ptr/Drmn/Concierge | B24: =+B14 -> 830.512 | C24: * | D24: 53.1 | E24: WKS.* | F24: 10 | J24: =+B24*F24 -> 8305.12 | L24: =SUM(H24:K24) -> 8305.12
A25: =+A16 -> Porter | B25: =+B16 -> 664.4096 | C25: * | D25: 3 | E25: WKS.* | F25: 0 | K25: =+B25*F25 -> 0 | L25: =SUM(H25:K25) -> 0
A26: Summer Relief | B26: =+B24*80% -> 664.4096 | D26: 3 | E26: Employees | F26: 18.67 | K26: =+D26*B26*F26 -> 37213.582 | L26: =SUM(H26:K26) -> 37213.582
A27: Subtotal | H27: =SUM(H22:H26) -> 0 | I27: =SUM(I22:I26) -> 3670.528 | J27: =SUM(J22:J26) -> 8305.12 | K27: =SUM(K22:K26) -> 37213.582 | L27: =SUM(L22:L26) -> 49189.23
A28: Unused Sick Time | D28: Union | F28: Coverage
A29: Unused Sick Time -Res Mgr | B29: =+B22/5 -> 339.292 | C29: * | D29: 13 | E29: days | F29: 10 | H29: =+B29*F29*H6 -> 3392.92 | L29: =SUM(H29:K29) -> 3392.92
A30: Unused Sick Time -Handyman | B30: =+B23/5 -> 183.5264 | C30: * | D30: 13 | E30: days | F30: 10 | I30: =+B30*F30*I6 -> 3670.528 | L30: =SUM(H30:K30) -> 3670.528
A31: Unused Sick Time -P/D/C | B31: =+B24/5 -> 166.1024 | C31: * | D31: 13 | E31: days | F31: 10 | J31: =+B31*F31*J6 -> 16610.24 | L31: =SUM(H31:K31) -> 16610.24
A32: Unused Sick Time-Porter | B32: =+B25/5 -> 132.88192 | C32: * | D32: 13 | E32: days | F32: 10 | J32: =+B32*F32*J7 -> 0 | K32: =+B32*F32*K6 -> 3986.4576 | L32: =SUM(H32:K32) -> 3986.4576
A33: Subtotal | H33: =SUM(H29:H32) -> 3392.92 | I33: =SUM(I29:I32) -> 3670.528 | J33: =SUM(J29:J32) -> 16610.24 | K33: =SUM(K29:K32) -> 3986.4576 | L33: =SUM(L29:L32) -> 27660.146
A34: * Coverage is for vacation time & Union unused sick time is paid even though not taken
A35: Total Vacation / Sick /Personal | F35: Total: | H35: =+H27+H33 -> 3392.92 | I35: =+I27+I33 -> 7341.056 | J35: =+J27+J33 -> 24915.36 | K35: =+K27+K33 -> 41200.039 | L35: =+L27+L33 -> 76849.375
A37: Holiday, Bonus: | D37: Union | G37: Coverage
A38: Super | B38: =+B29 -> 339.292 | C38: * | D38: 11 | E38: DAYS * | F38: 1.5 | G38: 0 | H38: =+B38*D38*F38*G38 -> 0 | L38: =SUM(H38:K38) -> 0
A39: =+A23 -> Handyman | B39: =+B30 -> 183.5264 | C39: * | D39: 11 | E39: DAYS * | F39: 1.5 | G39: 1 | I39: =+B39*D39*F39*G39 -> 3028.1856 | L39: =SUM(H39:K39) -> 3028.1856
A40: =+A24 -> Ptr/Drmn/Concierge | B40: =+B31 -> 166.1024 | C40: * | D40: 11 | E40: DAYS * | F40: 1.5 | G40: 4 | J40: =+B40*D40*F40*G40 -> 10962.758 | L40: =SUM(H40:K40) -> 10962.758
A41: Ptr/Drmn/Concierge -80% | B41: =+B32 -> 132.88192 | C41: * | D41: 11 | E41: DAYS * | F41: 1.5 | G41: 0 | K41: =+B41*D41*F41*G41 -> 0 | L41: =SUM(H41:K41) -> 0
A42: Bonus (Based on prior year merrit) | H42: 15000 | I42: =+B12*I6*2 -> 3670.528 | J42: =+B14*J6 -> 8305.12 | K42: =+B16*K6 -> 1993.2288 | L42: =SUM(H42:K42) -> 28968.877
...

Sheet Payroll
F1: =Income!E1 -> 444 East 86th Street Owners Corp. | P1: Super - Michael Stones
F2: Payroll | P2: per JS - 2021 increase pay rate for whole year
A3: Schedule B | F3: =' bud'!C3 -> For Year Ending 12/31/2026 | P3: as of 9/25 - budgets assume a 5% increase at time of union increases
I4: =pyrl!H4 -> Resident
A5: 32 BJ Rates | I5: =pyrl!H5 -> Manager | J5: Handyman | K5: Porter/Doorman | L5: Porter/Doorman | M5: Total | P5: Assistant Super - Mario Espejo(Board increased 9/23 5%)
A6: Base Wages:* | I6: 1 | J6: 3 | K6: 7 | L6: 1 | M6: =SUM(I6:L6) -> 12 | P6: Handymen
A7: Resident Manager | B7: =58.8105*40 -> 2352.42 | C7: /wk | E7: 24 | F7: Wks | I7: =SUM(B7*E7*$I$6) -> 56458.08 | M7: =SUM(I7:K7) -> 56458.08 | P7: David Leoniuk, Nelson Garcia
A8: Resident Manager | B8: =58.8105*1.05*40 -> 2470.041 | C8: /wk | E8: 28 | F8: Wks | I8: =SUM(B8*E8*$I$6) -> 69161.148
A9: Assistant Super | B9: =34.14*40 -> 1365.6 | C9: /wk | E9: 16 | F9: Wks | J9: =(B9*E9)*1 -> 21849.6 | M9: =SUM(I9:K9) -> 21849.6 | P9: Porters | S9: Doormen
A10: =+A9 -> Assistant Super | B10: =B9+42 -> 1407.6 | C10: =+C9 -> /wk | E10: 36 | F10: Wks | J10: =(B10*E10)*1 -> 50673.6 | M10: =SUM(I10:K10) -> 50673.6 | P10: Shiva Balram | Q10: 0.75 | S10: Walter Koch
A11: Handyman | B11: =32.61*40 -> 1304.4 | C11: =+C10 -> /wk | E11: 16 | F11: Wks | J11: =SUM(B11*E11)*2 -> 41740.8 | M11: =SUM(I11:K11) -> 41740.8 | P11: Sinayoko Bakary | S11: Jose Ortega
A12: =+A11 -> Handyman | B12: =+B11+42 -> 1346.4 | C12: =+C11 -> /wk | E12: 36 | F12: Wks | J12: =SUM(B12*E12)*2 -> 96940.8 | M12: =SUM(I12:K12) -> 96940.8 | P12: Nicky Boysie | S12: Rey Quinones
A13: Porter/Doorman | B13: =29.78*40 -> 1191.2 | C13: /wk | E13: 16 | F13: =+F9 -> Wks | K13: =SUM(B13*E13*$K$6) -> 133414.4 | M13: =SUM(I13:K13) -> 133414.4 | P13: Harbajan | S13: Jerry Rivera
A14: Porter/Doorman | B14: =+B13+40 -> 1231.2 | C14: /wk | E14: 36 | F14: Wks | K14: =SUM(B14*E14*$K$6) -> 310262.4 | M14: =SUM(I14:K14) -> 310262.4
A15: Porter/Doorman 75% | B15: =B13*75% -> 893.4 | C15: /wk | E15: 16 | F15: Wks | L15: =SUM(B15*E15*$L$6) -> 14294.4 | M15: =SUM(J15:L15) -> 14294.4
A16: Porter/Doorman 75% | B16: =B14*75% -> 923.4 | C16: /wk | E16: 32 | F16: Wks | L16: =SUM(B16*E16*$L$6) -> 29548.8 | M16: =SUM(J16:L16) -> 29548.8 | P16: Christian Acosta Sevilla replaced by Shiva Balram
A17: Porter/Doorman 85% | B17: =B14*85% -> 1046.52 | C17: /wk | E17: 4 | F17: Wks | L17: =SUM(B17*E17*$L$6) -> 4186.08 | M17: =SUM(J17:L17) -> 4186.08
F18: Gross Payroll: | I18: =SUM(I7:I17) -> 125619.23 | J18: =SUM(J7:J17) -> 211204.8 | K18: =SUM(K7:K17) -> 443676.8 | L18: =SUM(L7:L17) -> 48029.28 | M18: =SUM(M7:M17) -> 759368.96 | P18: Balram -hire 3/04/24 at 75%
P19: 85% 12/04/26 | R19: Pension 03/04/26
A20: Gross Payroll was multiplied by 1.135 to bring the pay year to | O20: factor spread | P20: 100% 08/04/27 | R20: Annuity 03/04/25
A21: 59 weeks to allow for relief, sick days, holidays, vacation pay, and OT: | H21: =59/52 -> 1.1346154 | I21: =+I18*$H$21 -> 142529.51 | J21: =+J18*$H$21 -> 239636.22 | K21: =+K18*$H$21 -> 503402.52 | L21: =+L18*$H$21 -> 54494.76 | M21: =SUM(I21:L21) -> 940063.01 | O21: =M21-M18 -> 180694.05
A22: Bonus | I22: 15000 | J22: =3000*3 -> 9000 | K22: =1800*K6 -> 12600 | L22: =1600*L6 -> 1600 | M22: =SUM(I22:L22) -> 38200
B23: Total Gross Wages: | I23: =SUM(I21:I22) -> 157529.51 | J23: =SUM(J21:J22) -> 248636.22 | K23: =SUM(K21:K22) -> 516002.52 | L23: =SUM(L21:L22) -> 56094.76 | M23: =SUM(M21:M22) -> 978263.01
A24: Payroll Taxes & Payroll Related Expenses:
A25: FICA-Gross Wages * | C25: 0.0765 | D25: (Using maximum estimated $183,600 for 2026) | I25: =+I23*$C$25 -> 12051.007 | J25: =+J23*$C$25 -> 19020.67 | K25: =+K23*$C$25 -> 39474.193 | L25: =+L23*$C$25 -> 4291.2491 | M25: =SUM(I25:L25) -> 74837.12
A26: SUI | B26: 0.02025 | C26: of 1st | E26: 12000 | I26: =+$B$26*$E$26*I6 -> 243 | J26: =+$B$26*$E$26*J6 -> 729 | K26: =+$B$26*$E$26*K6 -> 1701 | L26: =+$B$26*$E$26*L6 -> 243 | M26: =SUM(I26:L26) -> 2916
A27: FUI | B27: 0.006 | C27: of 1st | E27: 7000 | I27: =+$E$27*$B$27*I6 -> 42 | J27: =+$E$27*$B$27*J6 -> 126 | K27: =+$E$27*$B$27*K6 -> 294 | L27: =+$E$27*$B$27*L6 -> 42 | M27: =SUM(I27:L27) -> 504
A28: MTA | B28: 0.0034 | C28: of gross wages | I28: =I23*$B$28 -> 535.60033 | J28: =J23*$B$28 -> 845.36313 | K28: =K23*$B$28 -> 1754.4086 | L28: =L23*$B$28 -> 190.72218 | M28: =SUM(I28:L28) -> 3326.0942
A29: NYS Disability | C29: 45 | D29: per annum per emp | I29: =+C29*I6 -> 45 | J29: =+C29*J6 -> 135 | K29: =+C29*K6 -> 315 | L29: =+C29*L6 -> 45 | M29: =SUM(I29:L29) -> 540
A30: Paid Family Leave | B30: 0.00455 | C30: of gross wages | I30: =I23*$B$30 -> 716.75926 | J30: =J23*$B$30 -> 1131.2948 | K30: =K23*$B$30 -> 2347.8115 | L30: =L23*$B$30 -> 255.23116 | M30: =SUM(I30:L30) -> 4451.0967
A31: Worker's Comp. | B31: 0.05 | C31: of total gross wages | I31: =+$B$31*I23 -> 7876.4754 | J31: =+$B$31*J23 -> 12431.811 | K31: =+$B$31*K23 -> 25800.126 | L31: =+$B$31*L23 -> 2804.738 | M31: =SUM(I31:L31) -> 48913.15
A33: Non-Union Benefits(RM Only)
A34: Health | E34: =(283.85*10%)+283.85 -> 312.235 | F34: /month | I34: =+E34*12 -> 3746.82 | J34: 0 | K34: 0 | L34: 0 | M34: =SUM(I34:K34) -> 3746.82
E35: =(3289.72*10%)+3289.72 -> 3618.692 | F35: /month | I35: =+E35*12 -> 43424.304 | J35: 0 | K35: 0 | L35: 0 | M35: =SUM(I35:K35) -> 43424.304
A36: Union Benefits:
A37: Health | E37: =2113*12 -> 25356 | F37: /year | I37: 0 | J37: =+$E$37*J6 -> 76068 | K37: =+$E$37*K6 -> 177492 | L37: =+$E$37*L6 -> 25356 | M37: =SUM(I37:L37) -> 278916
A38: Pension | E38: =143*52 -> 7436 | F38: /year | I38: 0 | J38: =$E$38*J6 -> 22308 | K38: =$E$38*K6 -> 52052 | L38: =E38*L6 -> 7436 | M38: =SUM(I38:L38) -> 81796
A39: Supplemental Retirement | E39: =10*52 -> 520 | F39: /year | I39: 0 | J39: =$E$39*J6 -> 1560 | K39: =($E$39*7)+(10*43) -> 4070 | L39: =E39*L6 -> 520 | M39: =SUM(I39:L39) -> 6150
A40: Additional Supplemental Retirement | E40: =+E39 -> 520 | F40: /year | I40: 0 | J40: 0 | K40: =+E40*3 -> 1560 | L40: 0 | M40: =SUM(I40:L40) -> 1560
A41: Legal | E41: 199 | F41: /year | I41: 0 | J41: =+$E$41*J6 -> 597 | K41: =+$E$41*K6 -> 1393 | L41: =+$E$41*L6 -> 199 | M41: =SUM(I41:L41) -> 2189
...

Sheet Gas
F1: =+COV!C23 -> 444 East 86th Street Owners Corp.
F2: =+yrlycomp!B24 -> Electric
B3: Schedule C | F3: =+COV!C25 -> For Year Ending 12/31/2026
L5: Cooking Gas
E6: Hess A/C # 4321095000000102948425 | I6: ConEd A/C # 432109500000010 | M6: ConEd A/C # 4321095100000018 | P6: Total
B7: 2010 | D7: Amount | E7: MMBtu | F7: $ Per MMBtu | H7: Amount | I7: Therm | J7: $ Per therm | L7: Amount | M7: Therm | N7: $ Per therm | P7: Gas
B8: January | D8: 19848.57 | E8: 1819.5 | F8: =+D8/E8 -> 10.908805 | H8: 10491.31 | I8: 18607 | J8: =+H8/I8 -> 0.56383673 | L8: 341.32 | M8: 201 | N8: =+L8/M8 -> 1.6981095 | P8: =+D8+H8+L8 -> 30681.2
B9: February | D9: 12524.61 | E9: 1498.16 | F9: =+D9/E9 -> 8.3599949 | H9: 8652.85 | I9: 15106 | J9: =+H9/I9 -> 0.57280882 | L9: 300.24 | M9: 186 | N9: =+L9/M9 -> 1.6141935 | P9: =+D9+H9+L9 -> 21477.7
B10: March | D10: 7871.4 | E10: 1093.25 | F10: =+D10/E10 -> 7.2 | H10: 6103.59 | I10: 7629 | J10: =+H10/I10 -> 0.80005112 | L10: 225.1 | M10: 141 | N10: =+L10/M10 -> 1.5964539 | P10: =+D10+H10+L10 -> 14200.09
B11: April | D11: 4172 | E11: 673.99 | F11: =+D11/E11 -> 6.1900028 | H11: 4241.9 | I11: 5721 | J11: =+H11/I11 -> 0.74146128 | L11: 215.4 | M11: 139 | N11: =+L11/M11 -> 1.5496403 | P11: =+D11+H11+L11 -> 8629.3
B12: May | D12: 3769.82 | E12: 540.09 | F12: =+D12/E12 -> 6.9799848 | H12: 2932.64 | I12: 5207 | J12: =+H12/I12 -> 0.56321106 | L12: 225.9 | M12: 140 | N12: =+L12/M12 -> 1.6135714 | P12: =+D12+H12+L12 -> 6928.36
B13: June | D13: 3140.24 | E13: 465.22 | F13: =+D13/E13 -> 6.7500107 | H13: 2727.68 | I13: 4492 | J13: =+H13/I13 -> 0.60723063 | L13: 190.34 | M13: 113 | N13: =+L13/M13 -> 1.6844248 | P13: =+D13+H13+L13 -> 6058.26
B14: July | D14: 2898.41 | E14: 385.94 | F14: =+D14/E14 -> 7.5100016 | H14: 2145.86 | I14: 3297 | J14: =+H14/I14 -> 0.65085229 | L14: 171.55 | M14: 95 | N14: =+L14/M14 -> 1.8057895 | P14: =+D14+H14+L14 -> 5215.82
B15: August | D15: 2850.82 | E15: 372.17 | F15: =+D15/E15 -> 7.6599941 | H15: 2448.42 | I15: 3833 | J15: =+H15/I15 -> 0.63877381 | L15: 177.26 | M15: 96 | N15: =+L15/M15 -> 1.8464583 | P15: =+D15+H15+L15 -> 5476.5
B16: September | D16: 2863.71 | E16: 414.43 | F16: =+D16/E16 -> 6.9099969 | H16: 2565.57 | I16: 4105 | J16: =+H16/I16 -> 0.6249866 | L16: 217.26 | M16: 129 | N16: =+L16/M16 -> 1.684186 | P16: =+D16+H16+L16 -> 5646.54
B17: October | D17: 3881.87 | E17: 581.99 | F17: =+D17/E17 -> 6.6699943 | H17: 3863.77 | I17: 5676 | J17: =+H17/I17 -> 0.68072058 | L17: 237.08 | M17: 144 | N17: =+L17/M17 -> 1.6463889 | P17: =+D17+H17+L17 -> 7982.72
B18: November | D18: 5443.06 | E18: 908.69 | F18: =+D18/E18 -> 5.9900076 | H18: 5656.16 | I18: 10701 | J18: =+H18/I18 -> 0.52856369 | L18: 285.46 | M18: 192 | N18: =+L18/M18 -> 1.4867708 | P18: =+D18+H18+L18 -> 11384.68
B19: December | D19: 10286.98 | E19: 1506 | F19: =+D19/E19 -> 6.830664 | H19: 7369.89 | I19: 16098 | J19: =+H19/I19 -> 0.45781401 | L19: 262.32 | M19: 172 | N19: =+L19/M19 -> 1.5251163 | P19: =+D19+H19+L19 -> 17919.19
B20: Total | D20: =SUM(D8:D19) -> 79551.49 | E20: =SUM(E8:E19) -> 10259.43 | F20: =+D20/E20 -> 7.7539873 | H20: =SUM(H8:H19) -> 59199.64 | I20: =SUM(I8:I19) -> 100472 | J20: =+H20/I20 -> 0.5892153 | L20: =SUM(L8:L19) -> 2849.23 | M20: =SUM(M8:M19) -> 1748 | N20: =+L20/M20 -> 1.6299943 | P20: =SUM(P8:P19) -> 141600.36
E22: =E6 -> Hess A/C # 4321095000000102948425 | I22: =I6 -> ConEd A/C # 432109500000010 | M22: =M6 -> ConEd A/C # 4321095100000018 | P22: Total
B23: 2011 | D23: Amount | E23: =+E7 -> MMBtu | F23: =+F7 -> $ Per MMBtu | H23: Amount | I23: =+I7 -> Therm | J23: =+J7 -> $ Per therm | L23: Amount | M23: =+M7 -> Therm | N23: =+N7 -> $ Per therm | P23: Gas
B24: January | D24: 14440.28 | E24: 1895.05 | F24: =+D24/E24 -> 7.6199995 | H24: 8762.21 | I24: 19923 | J24: =+H24/I24 -> 0.43980374 | L24: 308.61 | M24: 204 | N24: =+L24/M24 -> 1.5127941 | P24: =+D24+H24+L24 -> 23511.1
B25: February | D25: 10708.02 | E25: 1392.46 | F25: =+D25/E25 -> 7.6900019 | H25: 6736.64 | I25: 13138 | J25: =+H25/I25 -> 0.51275993 | L25: 260 | M25: 167 | N25: =+L25/M25 -> 1.5568862 | P25: =+D25+H25+L25 -> 17704.66
B26: March | D26: 7627.95 | E26: 1147.06 | F26: =+D26/E26 -> 6.6500009 | H26: 4808.12 | I26: 9582 | J26: =+H26/I26 -> 0.50178668 | L26: 220.11 | M26: 143 | N26: =+L26/M26 -> 1.5392308 | P26: =+D26+H26+L26 -> 12656.18
B27: April | D27: 4698.64 | E27: 717.35 | F27: =+D27/E27 -> 6.5499965 | H27: 3798.46 | I27: 6249 | J27: =+H27/I27 -> 0.60785086 | L27: 217.77 | M27: 140 | N27: =+L27/M27 -> 1.5555 | P27: =+D27+H27+L27 -> 8714.87
B28: May | D28: 3355.02 | E28: 506.8 | F28: =+D28/E28 -> 6.6200079 | H28: 2707.61 | I28: 4345 | J28: =+H28/I28 -> 0.62315535 | L28: 204.5 | M28: 133 | N28: =+L28/M28 -> 1.537594 | P28: =+D28+H28+L28 -> 6267.13
B29: June | D29: 2760.06 | E29: 450.99 | F29: =+D29/E29 -> 6.1200027 | H29: 2624 | I29: 4488 | J29: =+H29/I29 -> 0.58467023 | L29: 177.27 | M29: 113 | N29: =+L29/M29 -> 1.5687611 | P29: =+D29+H29+L29 -> 5561.33
B30: July | D30: 2354.47 | E30: 374.32 | F30: =+D30/E30 -> 6.2899925 | H30: 2101.61 | I30: 3365 | J30: =+H30/I30 -> 0.62454978 | L30: 158.59 | M30: 95 | N30: =+L30/M30 -> 1.6693684 | P30: =+D30+H30+L30 -> 4614.67
B31: August | D31: 2331.28 | E31: 361.44 | F31: =+D31/E31 -> 6.4499779 | H31: 2156.95 | I31: 3519 | J31: =+H31/I31 -> 0.61294402 | L31: 155.05 | M31: 94 | N31: =+L31/M31 -> 1.6494681 | P31: =+D31+H31+L31 -> 4643.28
B32: September | D32: 2523.69 | E32: 413.72 | F32: =+D32/E32 -> 6.0999952 | H32: 1931.42 | I32: 3261 | J32: =+H32/I32 -> 0.59227844 | L32: 202.58 | M32: 141 | N32: =+L32/M32 -> 1.4367376 | P32: =+D32+H32+L32 -> 4657.69
B33: October | C33: Est | D33: =+E33*F33 -> 3897.8969 | E33: 600 | F33: =+J59 -> 6.4964949 | H33: =+I33*J33 -> 3595.4263 | I33: 5700 | J33: =+J60 -> 0.63077654 | L33: =+M33*N33 -> 229.51883 | M33: 150 | N33: =+J61 -> 1.5301255 | P33: =+D33+H33+L33 -> 7722.842
B34: November | C34: Est | D34: =+E34*F34 -> 6496.4949 | E34: 1000 | F34: =+J59 -> 6.4964949 | H34: =+I34*J34 -> 6938.542 | I34: 11000 | J34: =+J60 -> 0.63077654 | L34: =+M34*N34 -> 306.02511 | M34: 200 | N34: =+J61 -> 1.5301255 | P34: =+D34+H34+L34 -> 13741.062
B35: December | C35: Est | D35: =+E35*F35 -> 9907.1546 | E35: 1525 | F35: =+F34 -> 6.4964949 | H35: =+I35*J35 -> 10250.119 | I35: 16250 | J35: =+J34 -> 0.63077654 | L35: =+M35*N35 -> 267.77197 | M35: 175 | N35: =+N34 -> 1.5301255 | P35: =+D35+H35+L35 -> 20425.045
B36: Total | D36: =SUM(D24:D35) -> 71100.956 | E36: =SUM(E24:E35) -> 10384.19 | F36: =+D36/E36 -> 6.8470392 | H36: =SUM(H24:H35) -> 56411.107 | I36: =SUM(I24:I35) -> 100820 | J36: =+H36/I36 -> 0.55952298 | L36: =SUM(L24:L35) -> 2707.7959 | M36: =SUM(M24:M35) -> 1755 | N36: =+L36/M36 -> 1.5429036 | P36: =SUM(P24:P35) -> 130219.86
B38: Actual | E38: =E6 -> Hess A/C # 4321095000000102948425 | I38: =I6 -> ConEd A/C # 432109500000010 | M38: =M6 -> ConEd A/C # 4321095100000018 | P38: Total
B39: 2012 | D39: Amount | E39: =+E23 -> MMBtu | F39: $ Per Therm | H39: Amount | I39: =+I23 -> Therm | J39: $ Per Therm | L39: Amount | M39: =+M23 -> Therm | N39: $ Per Therm | P39: Gas
B40: January | L40: =+M40*N40 -> 331.53995 | M40: =SUM(M8+M24)/2 -> 202.5 | N40: =+L61 -> 1.6372343 | P40: =+D40+H40+L40 -> 331.53995
B41: February | L41: =+M41*N41 -> 288.97186 | M41: =SUM(M9+M25)/2 -> 176.5 | N41: =+N40 -> 1.6372343 | P41: =+D41+H41+L41 -> 288.97186
B42: March | L42: =+M42*N42 -> 232.48727 | M42: =SUM(M10+M26)/2 -> 142 | N42: =+N41 -> 1.6372343 | P42: =+D42+H42+L42 -> 232.48727
B43: April | L43: =+M43*N43 -> 228.39419 | M43: =SUM(M11+M27)/2 -> 139.5 | N43: =+N42 -> 1.6372343 | P43: =+D43+H43+L43 -> 228.39419
...

Sheet Electric
E1: =+yrlycomp!H1 -> 444 East 86th Street Owners Corp.
E2: Electric
B3: Schedule C | E3: =+yrlycomp!H3 -> For Year Ending 12/31/2026
B5: G/L | N5: New Account Number
B6: 5255-0000 | N6: 50834100005
D7: Con Ed #49-4182-7002-0000-8 new account #50834100005 | U7: 0000-8 General
B8: 2024 | D8: Con Ed | E8: Esco | F8: Total | G8: KWH | H8: Con Ed $/Per KWH | I8: ESCO $/ KWH | K8: $/Per KWH
B9: January | D9: 7382.01 | E9: 7286.49 | F9: =+D9+E9 -> 14668.5 | G9: 73939 | H9: =+D9/G9 -> 0.099839192 | I9: =+E9/G9 -> 0.098547316 | K9: =+H9+I9 -> 0.19838651 | U9: 0002-0
B10: February | D10: 6811.74 | E10: 7046.63 | F10: =+D10+E10 -> 13858.37 | G10: 73452 | H10: =+D10/G10 -> 0.092737298 | I10: =+E10/G10 -> 0.095935169 | K10: =+H10+I10 -> 0.18867247 | R10: =339200/4 -> 84800
B11: March | D11: 6901.65 | E11: 6065.4 | F11: =+D11+E11 -> 12967.05 | G11: 66666 | H11: =+D11/G11 -> 0.10352579 | I11: =+E11/G11 -> 0.09098191 | K11: =+H11+I11 -> 0.1945077
B12: April | D12: 5500.34 | E12: 5159.7 | F12: =+D12+E12 -> 10660.04 | G12: 56446 | H12: =+D12/G12 -> 0.097444283 | I12: =+E12/G12 -> 0.091409489 | K12: =+H12+I12 -> 0.18885377
B13: May | D13: 7805.2 | E13: 4041.69 | F13: =+D13+E13 -> 11846.89 | G13: 44188 | H13: =+D13/G13 -> 0.17663619 | I13: =+E13/G13 -> 0.091465783 | K13: =+H13+I13 -> 0.26810197
B14: June | D14: 10849.36 | E14: 7758.64 | F14: =+D14+E14 -> 18608 | G14: 74572 | H14: =+D14/G14 -> 0.14548839 | I14: =+E14/G14 -> 0.10404227 | K14: =+H14+I14 -> 0.24953065
B15: July | D15: 11785.74 | E15: 12199.59 | F15: =+D15+E15 -> 23985.33 | G15: 111481 | H15: =+D15/G15 -> 0.10571972 | I15: =+E15/G15 -> 0.10943201 | K15: =+H15+I15 -> 0.21515173
B16: August | D16: 10654.93 | E16: 11003.19 | F16: =+D16+E16 -> 21658.12 | G16: 108129 | H16: =+D16/G16 -> 0.09853906 | I16: =+E16/G16 -> 0.10175984 | K16: =+H16+I16 -> 0.2002989
B17: September | D17: 11838.1 | E17: 10736.45 | F17: =+D17+E17 -> 22574.55 | G17: 109438 | H17: =+D17/G17 -> 0.10817175 | I17: =+E17/G17 -> 0.09810532 | K17: =+H17+I17 -> 0.20627707
B18: October | D18: 9245.5 | E18: 7797.58 | F18: =+D18+E18 -> 17043.08 | G18: 78130 | H18: =+D18/G18 -> 0.11833483 | I18: =+E18/G18 -> 0.099802637 | K18: =+H18+I18 -> 0.21813746
B19: November | D19: 5738.9 | E19: 5871.58 | F19: =+D19+E19 -> 11610.48 | G19: 59991 | H19: =+D19/G19 -> 0.095662683 | I19: =+E19/G19 -> 0.097874348 | K19: =+H19+I19 -> 0.19353703
B20: December | D20: 7449.74 | E20: 9610.08 | F20: =+D20+E20 -> 17059.82 | G20: 69126 | H20: =+D20/G20 -> 0.10777045 | I20: =+E20/G20 -> 0.13902265 | K20: =+H20+I20 -> 0.2467931
B21: Total | D21: =SUM(D9:D20) -> 101963.21 | E21: =SUM(E9:E20) -> 94577.02 | F21: =SUM(F9:F20) -> 196540.23 | G21: =SUM(G9:G20) -> 925558 | H21: =+D21/G21 -> 0.11016404 | I21: =+E21/G21 -> 0.10218379 | K21: =F21/G21 -> 0.21234783
D23: =D7 -> Con Ed #49-4182-7002-0000-8 new account #50834100005
B24: =B8+1 -> 2025 | D24: =+D8 -> Con Ed | E24: ESCO | F24: Total | G24: KWH | H24: Con Ed $/KWH | I24: ESCO $/ KWH | K24: $/Per KWH
B25: January | D25: 6848.26 | E25: 13612.08 | F25: =D25+E25 -> 20460.34 | G25: 67982 | H25: =+D25/G25 -> 0.10073637 | I25: =E25/G25 -> 0.20023065 | K25: =+H25+I25 -> 0.30096702
B26: February | D26: 5385.08 | E26: 10461.16 | F26: =D26+E26 -> 15846.24 | G26: 56840 | H26: =D26/G26 -> 0.094741027 | I26: =E26/G26 -> 0.18404574 | K26: =SUM(H26:I26) -> 0.27878677
B27: March | D27: 5090.12 | E27: 6650.44 | F27: =D27+E27 -> 11740.56 | G27: 53836 | H27: =D27/G27 -> 0.094548629 | I27: =E27/G27 -> 0.12353147 | K27: =SUM(H27:I27) -> 0.2180801
B28: April | D28: 5271.22 | E28: 6337.48 | F28: =D28+E28 -> 11608.7 | G28: 54952 | H28: =D28/G28 -> 0.095924079 | I28: =E28/G28 -> 0.11532756 | K28: =SUM(H28:I28) -> 0.21125164
B29: May | D29: 8083.76 | E29: 7250.93 | F29: =D29+E29 -> 15334.69 | G29: 71005 | H29: =D29/G29 -> 0.11384776 | I29: =E29/G29 -> 0.10211858 | K29: =SUM(H29:I29) -> 0.21596634
B30: June | D30: 10959.29 | E30: 10950.23 | F30: =D30+E30 -> 21909.52 | G30: 94615 | H30: =D30/G30 -> 0.11583037 | I30: =E30/G30 -> 0.11573461 | K30: =SUM(H30:I30) -> 0.23156497
B31: July | D31: 14114.42 | E31: 15720.57 | F31: =D31+E31 -> 29834.99 | G31: 114667 | H31: =D31/G31 -> 0.12309051 | I31: =E31/G31 -> 0.1370976 | K31: =SUM(H31:I31) -> 0.26018811
B32: August | C32: Est | D32: =G32*H32 -> 15287.732 | E32: =+G32*I32 -> 18484.71 | F32: =D32+E32 -> 33772.442 | G32: =+(G16+G78)/2 -> 144864.5 | H32: =SUM(H25:H31)/7 -> 0.10553125 | I32: 0.1276 | K32: =K31 -> 0.26018811
B33: September | C33: Est | D33: =G33*H33 -> 15483.439 | E33: =+G33*I33 -> 18721.344 | F33: =D33+E33 -> 34204.784 | G33: =+(G17+G79)/2 -> 146719 | H33: =H32 -> 0.10553125 | I33: =I32 -> 0.1276 | K33: =K32 -> 0.26018811
B34: October | C34: Est | D34: =G34*H34 -> 9544.0879 | E34: =+G34*I34 -> 11539.953 | F34: =D34+E34 -> 21084.04 | G34: =+(G18+G80)/2 -> 90438.5 | H34: =H32 -> 0.10553125 | I34: =I32 -> 0.1276 | K34: =K33 -> 0.26018811
B35: November | C35: Est | D35: =G35*H35 -> 7423.4374 | E35: =+G35*I35 -> 8975.8306 | F35: =D35+E35 -> 16399.268 | G35: =+(G19+G81)/2 -> 70343.5 | H35: =H32 -> 0.10553125 | I35: =I32 -> 0.1276 | K35: =K34 -> 0.26018811
B36: December | C36: Est | D36: =G36*H36 -> 8290.8515 | E36: =+G36*I36 -> 10024.639 | F36: =D36+E36 -> 18315.49 | G36: =+(G20+G82)/2 -> 78563 | H36: =H32 -> 0.10553125 | I36: =I32 -> 0.1276 | K36: =+K35 -> 0.26018811
B37: Total | D37: =SUM(D25:D36) -> 111781.7 | E37: =SUM(E25:E36) -> 138729.37 | F37: =SUM(F25:F36) -> 250511.06 | G37: =SUM(G25:G36) -> 1044825.5 | H37: =D37/G37 -> 0.106986 | I37: =E37/G37 -> 0.13277755 | K37: =+F37/G37 -> 0.23976354
B39: Budget | D39: =D23 -> Con Ed #49-4182-7002-0000-8 new account #50834100005
B40: =B24+1 -> 2026 | D40: =+D24 -> Con Ed | E40: =E24 -> ESCO | F40: Total | G40: =G24 -> KWH | H40: =H24 -> Con Ed $/KWH | I40: ESCO $/KWH | K40: =K24 -> $/Per KWH
B41: January | D41: =G41*H41 -> 7720.1675 | E41: =G41*I41 -> 9657.7241 | F41: =D41+E41 -> 17377.892 | G41: =+(G9+G25)/2 -> 70960.5 | H41: =$H$25*$I$57+H25 -> 0.10879528 | I41: =I64 -> 0.1361 | K41: =+H41+I41 -> 0.24489528
B42: February | D42: =G42*H42 -> 6665.7589 | E42: =G42*I42 -> 8866.3706 | F42: =D42+E42 -> 15532.129 | G42: =+(G10+G26)/2 -> 65146 | H42: =$H$26*$I$57+H26 -> 0.10232031 | I42: =I64 -> 0.1361 | K42: =SUM(H42:I42) -> 0.23842031
B43: March | D43: =G43*H43 -> 6152.3814 | E43: =G43*I43 -> 8200.1611 | F43: =D43+E43 -> 14352.543 | G43: =+(G11+G27)/2 -> 60251 | H43: =H27*I57+H27 -> 0.10211252 | I43: =I64 -> 0.1361 | K43: =SUM(H43:I43) -> 0.23821252
...

Sheet Electric 2
E1: =+yrlycomp!H1 -> 444 East 86th Street Owners Corp.
E2: Electric
B3: Schedule C | E3: =+yrlycomp!H3 -> For Year Ending 12/31/2026
B5: G/L
B6: 5255-0000
D7: Con Ed #42-2039-0422-3500-0 new account #70788-12000-7
B8: =Electric!B8 -> 2024 | D8: Con Ed | F8: KWH | H8: $/Per KWH | L8: Super
B9: January | D9: 204.22 | F9: 491 | H9: =+D9/F9 -> 0.41592668
B10: February | D10: 151.33 | F10: 374 | H10: =+D10/F10 -> 0.40462567
B11: March | D11: 142.14 | F11: 322 | H11: =+D11/F11 -> 0.44142857 | K11: 70788120007
B12: April | D12: 124.25 | F12: 309 | H12: =+D12/F12 -> 0.40210356
B13: May | D13: 189.94 | F13: 523 | H13: =+D13/F13 -> 0.363174
B14: June | D14: 599.82 | F14: 1649 | H14: =+D14/F14 -> 0.36374773
B15: July | D15: 507.66 | F15: 1355 | H15: =+D15/F15 -> 0.37465683
B16: August | D16: 436.46 | F16: 1152 | H16: =+D16/F16 -> 0.37887153
B17: September | D17: 313.62 | F17: 778 | H17: =+D17/F17 -> 0.40311054
B18: October | D18: 186.68 | F18: 418 | H18: =+D18/F18 -> 0.44660287
B19: November | D19: 178.62 | F19: 415 | H19: =+D19/F19 -> 0.43040964
